Workbook

Sheet Arrosants
B1: Civil | C1: Nom | D1: Réf | E1: annee | F1: Rue | G1: Quartier | H1: Code | I1: Ville | J1: Numéro des parcelles | K1: m2 | L1: Taxes P/année | M1: 0.4 | N1: Cot Arrondie | O1: Mise à Jour
B2: M. | C2: AGUIAR FONSECA Armindo | D2: 1 | E2: 2025 | F2: 5011 Bld de la Valée | H2: 06440 | I2: PEILLON | J2: C 1269 Les Novaines | K2: 465 | L2: =VLOOKUP(K2,'Tarifs 40%'!$B$4:$C$20,2,TRUE) -> 23.5 | M2: =L2*40/100 -> 9.4 | N2: 9.45 | IV2: 5011, Bd de la Vallée
B3: Mme | C3: ALAGIA Antonia | D3: 2 | E3: 2025 | F3: 45, Boulevard Jean Behra | G3: BORGHEAS | H3: 06100 | I3: NICE | J3: C 1555 C 1556 Le Plan | K3: 700 | L3: =VLOOKUP(K3,'Tarifs 40%'!$B$4:$C$20,2,TRUE) -> 33.3 | M3: =L3*40/100 -> 13.32 | N3: 13.35
B4: M. | C4: ALLISIO ANTOINE | D4: 3 | E4: 2025 | F4: 89 Vieux Chemin de Laghet | H4: 06340 | I4: DRAP | J4: C 1087 Les Novaines | K4: 750 | L4: =VLOOKUP(K4,'Tarifs 40%'!$B$4:$C$20,2,TRUE) -> 33.3 | M4: =L4*40/100 -> 13.32 | N4: 13.35 | O4: 45402
B5: M. | C5: AMBERT Nicolas & VALLADOU Jennifer | D5: 4 | E5: 2025 | F5: 5501 Bld de la Vallée | G5: LES NOVAINES | H5: 06440 | I5: PEILLON | J5: C 912 , C1349 | K5: 585 | L5: =VLOOKUP(K5,'Tarifs 40%'!$B$4:$C$20,2,TRUE) -> 33.3 | M5: =L5*40/100 -> 13.32 | N5: 13.35
B6: M. | C6: ARMANDO JOSEPH | D6: 5 | E6: 2025 | F6: chez Mr CENTINI Guido | G6: LES NOVAINES | H6: 06440 | I6: PEILLON | J6: C 1089 Les Novaines | K6: 473 | L6: =VLOOKUP(K6,'Tarifs 40%'!$B$4:$C$20,2,TRUE) -> 23.5 | M6: =L6*40/100 -> 9.4 | N6: 9.45
C7: AS IMMO Sci | D7: 6 | E7: 2025 | F7: 2 Rue Guiglionda de Sainte Agathe | H7: 06300 | I7: NICE | J7: B 321,322 Ste Thècle | K7: 1099 | L7: =VLOOKUP(K7,'Tarifs 40%'!$B$4:$C$20,2,TRUE) -> 48 | M7: =L7*40/100 -> 19.2 | N7: 19.45
B8: M. | C8: ASENCIO Pierre | D8: 7 | E8: 2025 | F8: 33 Ave Denis Semeria | H8: 06300 | I8: NICE | J8: C 1185 Les Près | K8: 911 | L8: =VLOOKUP(K8,'Tarifs 40%'!$B$4:$C$20,2,TRUE) -> 39.5 | M8: =L8*40/100 -> 15.8 | N8: 15.85
B9: M. | C9: AUSELO CHRISTOPHE | D9: 8 | E9: 2025 | F9: 919 Route de Preisses | G9: STE THECLE | H9: 06440 | I9: PEILLON | J9: B 491 Ste Thècle | K9: 435 | L9: =VLOOKUP(K9,'Tarifs 40%'!$B$4:$C$20,2,TRUE) -> 23.5 | M9: =L9*40/100 -> 9.4 | N9: 9.45
B10: M. | C10: BAIO JACQUES | D10: 9 | E10: 2025 | F10: 65 RUE DES SOURCES | G10: STE THECLE | H10: 06440 | I10: PEILLON | J10: B 478,481 Ste Thècle | K10: 636 | L10: =VLOOKUP(K10,'Tarifs 40%'!$B$4:$C$20,2,TRUE) -> 33.3 | M10: =L10*40/100 -> 13.32 | N10: 13.35
B11: M. | C11: BALLAREL ANDRÉ | D11: 10 | E11: 2025 | F11: 526 PDE A. PASSERON | G11: BORGHEAS | H11: 06440 | I11: PEILLON | J11: C 173 Le Plan de Borghéas(250m) | K11: 250 | L11: =VLOOKUP(K11,'Tarifs 40%'!$B$4:$C$20,2,TRUE) -> 13.6 | M11: =L11*40/100 -> 5.44 | N11: 5.45
B12: M. | C12: BALLAREL LOUIS | D12: 11 | E12: 2025 | F12: 16, avenue MENDIGUREN | G12: BORGHEAS | H12: 06000 | I12: NICE | J12: C 172 Le Plan Borghéas | K12: 205 | L12: =VLOOKUP(K12,'Tarifs 40%'!$B$4:$C$20,2,TRUE) -> 13.6 | M12: =L12*40/100 -> 5.44 | N12: 5.45
B13: M. | C13: BARELLI Jacques | D13: 12 | E13: 2025 | F13: 187 route de CHATEAUNEUF | G13: Quartier La Lèbre | H13: 06390 | I13: BENDEJUN | J13: C 389 (575m²) Plan des Pins Borghéas, B 759(1548),760(413) Châteauvieux | K13: 2536 | L13: =VLOOKUP(K13,'Tarifs 40%'!$B$4:$C$20,2,TRUE) -> 85.4 | M13: =L13*40/100 -> 34.16 | N13: 34.15
B14: M. | C14: BARONI Jean Paul | D14: 13 | E14: 2025 | F14: 4727 ROUTE DE ST JEANNET | G14: LES NOVAINES | H14: 06700 | I14: ST LAURENT DU VAR | J14: C 1232,1235,1236,1237 Les Novaines | K14: 377 | L14: =VLOOKUP(K14,'Tarifs 40%'!$B$4:$C$20,2,TRUE) -> 23.5 | M14: =L14*40/100 -> 9.4 | N14: 9.45
B15: M. | C15: BARRIERE YVETTE | D15: 14 | E15: 2025 | F15: 254, CHE RIBA DAU PAIOUN | G15: LES PRES | H15: 06440 | I15: PEILLON | J15: C 717 (170) 718 (162) Les Prés | K15: 332 | L15: =VLOOKUP(K15,'Tarifs 40%'!$B$4:$C$20,2,TRUE) -> 23.5 | M15: =L15*40/100 -> 9.4 | N15: 9.45
B16: M. | C16: BASSO JEAN-MARC | D16: 15 | E16: 2025 | F16: 157, RAYANA SOUTRANA | G16: STE THECLE | H16: 06440 | I16: PEILLON | J16: B 288,293,291 292 295 Ste Thècle | K16: 2244 | L16: =VLOOKUP(K16,'Tarifs 40%'!$B$4:$C$20,2,TRUE) -> 78 | M16: =L16*40/100 -> 31.2 | N16: 31.25
B17: M. | C17: BEDESCHI CHRISTOPHE | D17: 16 | E17: 2025 | F17: 631, AVENUE DE L'HOTEL DE VILLE | G17: STE THECLE | H17: 06440 | I17: PEILLON | J17: B 419, B420 Ste Thècle | K17: 100 | L17: =VLOOKUP(K17,'Tarifs 40%'!$B$4:$C$20,2,TRUE) -> 13.6 | M17: =L17*40/100 -> 5.44 | N17: 5.45
B18: M. | C18: BELICCHI MARIE | D18: 17 | E18: 2025 | F18: 145 AVE MAL LYAUTEY | G18: Le Sagittaire Bt B | H18: 06000 | I18: NICE | J18: B 441,442 Ste Thècle | K18: 555 | L18: =VLOOKUP(K18,'Tarifs 40%'!$B$4:$C$20,2,TRUE) -> 33.3 | M18: =L18*40/100 -> 13.32 | N18: 13.35
B19: Mme | C19: BELLARDI Raymonde | D19: 18 | E19: 2025 | F19: 3502 BD DE LA VALLÉE | G19: LES MOULINS | H19: 06440 | I19: PEILLON | J19: B 942 Capeou | K19: 43 | L19: =VLOOKUP(K19,'Tarifs 40%'!$B$4:$C$20,2,TRUE) -> 13.6 | M19: =L19*40/100 -> 5.44 | N19: 5.45
B20: M. | C20: BELLONE LAURENT | D20: 19 | E20: 2025 | F20: 5264 BD DE LA VALLÉE | G20: STE THECLE | H20: 06440 | I20: PEILLON | J20: C 1023,1338, les Novaines | K20: 1810 | L20: =VLOOKUP(K20,'Tarifs 40%'!$B$4:$C$20,2,TRUE) -> 69.3 | M20: =L20*40/100 -> 27.72 | N20: 27.75
... B23: M. | C23: BERNARDINI DANIEL | D23: 22 | E23: 2025 | F23: 199 CH. CANTON SOUBRAN | G23: SAINTE-THECLE | H23: 06440 | I23: PEILLON | J23: A 802 le Calpre | K23: 875 | L23: =VLOOKUP(K23,'Tarifs 40%'!$B$4:$C$20,2,TRUE) -> 39.5 | M23: =L23*40/100 -> 15.8 | N23: 15.85
B24: M. | C24: BERNARDINI MARCEL | D24: 23 | E24: 2025 | F24: 4 BD ST ROCH | H24: 06300 | I24: NICE | J24: B 770,771,772 Chateauvieux | K24: 259 | L24: =VLOOKUP(K24,'Tarifs 40%'!$B$4:$C$20,2,TRUE) -> 23.5 | M24: =L24*40/100 -> 9.4 | N24: 9.45
B25: M. | C25: BIANCHERI ERIC | D25: 24 | E25: 2025 | F25: 15, rue des LUCIOLES | G25: Villa les IRIS | H25: 06240 | I25: BEAUSOLEIL | J25: C1136 996 1002 1003 Les Novaines | K25: 2994 | L25: =VLOOKUP(K25,'Tarifs 40%'!$B$4:$C$20,2,TRUE) -> 85.4 | M25: =L25*40/100 -> 34.16 | N25: 34.15
B26: M. | C26: BLANC Eric | D26: 25 | E26: 2025 | F26: 5160, BOULEVARD DE LA VALLEE | G26: LES NOVAINES | H26: 06440 | I26: PEILLON | J26: C 1051 (893) 1052 (2) 1053 (1040) Les Novaines | K26: 1935 | L26: =VLOOKUP(K26,'Tarifs 40%'!$B$4:$C$20,2,TRUE) -> 69.3 | M26: =L26*40/100 -> 27.72 | N26: 27.75
B27: M. | C27: BODINO JEAN | D27: 26 | E27: 2025 | F27: 250 route de CHATEAUVIEUX | G27: CHATEAUVIEUX | H27: 06440 | I27: PEILLON | J27: B 747 Châteauvieux | K27: 88 | L27: =VLOOKUP(K27,'Tarifs 40%'!$B$4:$C$20,2,TRUE) -> 13.6 | M27: =L27*40/100 -> 5.44 | N27: 5.45
B28: M. | C28: BOITRAN MARC | D28: 27 | E28: 2025 | F28: 1 Bd du Docteur ROUX | G28: LES PRES | H28: 06440 | I28: L'ESCARENE | J28: C 723 (115) 724 (403) | K28: 518 | L28: =VLOOKUP(K28,'Tarifs 40%'!$B$4:$C$20,2,TRUE) -> 33.3 | M28: =L28*40/100 -> 13.32 | N28: 13.35 | O28: 45561
B29: M. | C29: BONIN Wattel | D29: 28 | E29: 2025 | F29: 5028 Bld De la Vallée | H29: 06440 | I29: PEILLON | J29: C 1063 1064 | K29: 561 | L29: =VLOOKUP(K29,'Tarifs 40%'!$B$4:$C$20,2,TRUE) -> 33.3 | M29: =L29*40/100 -> 13.32 | N29: 13.35
B30: M. | C30: BONSIGNORI J-PIERRE | D30: 29 | E30: 2025 | F30: Les Mimosas 18, rue PLAINE DE CIMIEZ | G30: CHATEAUVIEUX | H30: 06000 | I30: NICE | J30: B 729,730,731,734,743 Châteauvieux | K30: 934 | L30: =VLOOKUP(K30,'Tarifs 40%'!$B$4:$C$20,2,TRUE) -> 39.5 | M30: =L30*40/100 -> 15.8 | N30: 15.85
B31: M. | C31: BONZI Frederic | D31: 30 | E31: 2025 | F31: VILLA FLORE Bloc A 3 Av de VILAINE | H31: 06240 | I31: BEAUSOLEIL | J31: C 980 (658m2) Les Novaines | K31: 658 | L31: =VLOOKUP(K31,'Tarifs 40%'!$B$4:$C$20,2,TRUE) -> 33.3 | M31: =L31*40/100 -> 13.32 | N31: 13.35
B32: M. | C32: BONZI J-LAURENT | D32: 31 | E32: 2025 | F32: 64 RAYANA SOUBRANA | G32: STE THECLE | H32: 06440 | I32: PEILLON | J32: B 320 Ste Thècle | K32: 1000 | L32: =VLOOKUP(K32,'Tarifs 40%'!$B$4:$C$20,2,TRUE) -> 39.5 | M32: =L32*40/100 -> 15.8 | N32: 15.85
B33: M. | C33: BONZOM JEAN PIERRE | D33: 32 | E33: 2025 | F33: 39, AVENUE DE BUENOS AYRES | H33: 06100 | I33: NICE | J33: C 729 (319), 730 (98) Les Prés | K33: 417 | L33: =VLOOKUP(K33,'Tarifs 40%'!$B$4:$C$20,2,TRUE) -> 23.5 | M33: =L33*40/100 -> 9.4 | N33: 9.45
B34: M. | C34: BOSSIS Georges | D34: 33 | E34: 2025 | F34: 11 Ave Vadiletta | H34: 06100 | I34: NICE | J34: C 691,692,Les Près | K34: 441 | L34: =VLOOKUP(K34,'Tarifs 40%'!$B$4:$C$20,2,TRUE) -> 23.5 | M34: =L34*40/100 -> 9.4 | N34: 9.45
B35: M. | C35: BOYER PHILIPPE | D35: 34 | E35: 2025 | F35: 12,RUE DES SOURCES | G35: STE THECLE | H35: 06440 | I35: PEILLON | J35: B 436 Ste Thècle | K35: 228 | L35: =VLOOKUP(K35,'Tarifs 40%'!$B$4:$C$20,2,TRUE) -> 13.6 | M35: =L35*40/100 -> 5.44 | N35: 5.45
B36: M. | C36: BRESNU CASIMIR | D36: 35 | E36: 2025 | F36: 10, BD DE LA REPUBLIQUE | H36: 06240 | I36: BEAUSOLEIL | J36: B 739 Châteauvieux | K36: 131 | L36: =VLOOKUP(K36,'Tarifs 40%'!$B$4:$C$20,2,TRUE) -> 13.6 | M36: =L36*40/100 -> 5.44 | N36: 5.45
B37: M. | C37: BRETAGNE Suzanne | D37: 36 | E37: 2025 | F37: 1857 Route de Puget | G37: BORGHEAS | H37: 06700 | I37: ST. LAURENT DU VAR | J37: C 392 Le Plans des Pin | K37: 175 | L37: =VLOOKUP(K37,'Tarifs 40%'!$B$4:$C$20,2,TRUE) -> 13.6 | M37: =L37*40/100 -> 5.44 | N37: 5.45
B38: M. | C38: BREWAEYS MARC | D38: 37 | E38: 2025 | F38: 1699 ROUTE DE LEVENS | G38: LES PRES | H38: 06690 | I38: TOURRETTE LEVENS | J38: C 731,732 les Près | K38: 1500 | L38: =VLOOKUP(K38,'Tarifs 40%'!$B$4:$C$20,2,TRUE) -> 54.4 | M38: =L38*40/100 -> 21.76 | N38: 21.75
B39: Mme | C39: BRUNET VERONIQUE | D39: 38 | E39: 2025 | F39: 70 Avenue Vincent ARNAUD | H39: 06300 | I39: NICE | J39: C 397 398 399 Le Plan Borghéas, C433 748 749 750 751 752 Châteauvieux | K39: 4457 | L39: =VLOOKUP(K39,'Tarifs 40%'!$B$4:$C$20,2,TRUE) -> 93.3 | M39: =L39*40/100 -> 37.32 | N39: 37.45
B40: Mme | C40: CABANES Christine | D40: 39 | E40: 2025 | F40: 155 Quartier Rayana Soutrana | G40: STE THECLE | H40: 06440 | I40: PEILLON | J40: B 289, 290, 400 (665) Ste Thècle | K40: 1362 | L40: =VLOOKUP(K40,'Tarifs 40%'!$B$4:$C$20,2,TRUE) -> 54.4 | M40: =L40*40/100 -> 21.76 | N40: 21.75
B41: M. | C41: CALBOCCI GÉRARD | D41: 40 | E41: 2025 | F41: 455 Route DE CHÂTEAUVIEUX | G41: CHATEAUVIEUX | H41: 06440 | I41: PEILLON | J41: B 780 781 Châteauvieux | K41: 294 | L41: =VLOOKUP(K41,'Tarifs 40%'!$B$4:$C$20,2,TRUE) -> 23.5 | M41: =L41*40/100 -> 9.4 | N41: 9.45
B42: Mme | C42: CALLEGARI Jocelyne | D42: 41 | E42: 2025 | F42: 90, Camin LOU VALADOUN | G42: LE MOULIN | H42: 06440 | I42: PEILLON | J42: B 1123 les Moulins | K42: 3600 | L42: =VLOOKUP(K42,'Tarifs 40%'!$B$4:$C$20,2,TRUE) -> 93.3 | M42: =L42*40/100 -> 37.32 | N42: 37.45
...

Sheet Feuille Pres
B1: FEUILLE DE PRESENCE ASSEMLEE GENERALE STATUTAIRE PEILLON LE 11 AVRIL 2025 18h Salle Conseil Municipal
B2: Nom | C2: Ville | D2: SIGNATURE
B3: AGUIAR FONSECA Armindo | C3: PEILLON
B4: ALAGIA Antonia | C4: NICE
B5: ALLISIO ANTOINE | C5: DRAP
B6: AMBERT Nicolas & VALLADOU Jennifer | C6: PEILLON
B7: ARMANDO JOSEPH | C7: PEILLON
B8: AS IMMO Sci | C8: NICE
B9: ASENCIO Pierre | C9: NICE
B10: AUSELO CHRISTOPHE | C10: PEILLON
B11: BAIO JACQUES | C11: PEILLON
B12: BALLAREL ANDRÉ | C12: PEILLON
B13: BALLAREL LOUIS | C13: NICE
B14: BARELLI Jacques | C14: BENDEJUN
... B200: VOLTIER Jean Mihel | C200: PEILLON
B201: PUISANTS | C201: VILLE | D201: SIGNATURE
B202: BRUCIAMACCHIE | C202: LES NOVAINES
B203: D'INCA René | C203: L' AIGLON
B204: GASTALDI Sabée | C204: NICE NORD
B205: MAMONE | C205: LES NOVAINES
B206: PICART Yves | C206: STE THECLE
B207: SPIES Jean Pierre | C207: STE THECLE
B208: Mise à Jour 28/03/25

Sheet Tarifs 40%
A1: Tarif
B2: BAREME de reference 2024
B3: Surface ref | C3: Tarif
B4: 1 | C4: 13.6
B5: 251 | C5: 23.5
B6: 501 | C6: 33.3
B7: 751 | C7: 39.5
B8: 1001 | C8: 48
B9: 1251 | C9: 54.4
B10: 1501 | C10: 60.7
B11: 1751 | C11: 69.3
B12: 2001 | C12: 78
B13: 2501 | C13: 85.4
B14: 3001 | C14: 93.3

Sheet Base tarifs
B2: TARIFS DE BASE | F2: 0.4
B4: Base m² | C4: Plafond m² | D4: Tarifs 2022
B5: 1 | C5: 250 | D5: 13.6 | F5: =D5*40/100 -> 5.44
B6: 251 | C6: 500 | D6: 23.5 | F6: =D6*40/100 -> 9.4
B7: 501 | C7: 750 | D7: 33.3 | F7: =D7*40/100 -> 13.32
B8: 751 | C8: 1000 | D8: 39.5 | F8: =D8*40/100 -> 15.8
B9: 1001 | C9: 1250 | D9: 48.01 | F9: =D9*40/100 -> 19.204
B10: 1251 | C10: 1500 | D10: 54.4 | F10: =D10*40/100 -> 21.76
B11: 1501 | C11: 1750 | D11: 60.7 | F11: =D11*40/100 -> 24.28
B12: 1751 | C12: 2000 | D12: 69.3 | F12: =D12*40/100 -> 27.72
B13: 2001 | C13: 2500 | D13: 78.01 | F13: =D13*40/100 -> 31.204
B14: 2501 | C14: 3000 | D14: 85.4 | F14: =D14*40/100 -> 34.16
B15: 3001 | C15: 3500 | D15: 93.3 | F15: =D15*40/100 -> 37.32
B16: 3501 | C16: 999999 | F16: =D16*40/100 -> 0
